Traceback (most recent call last):
  File "C:\Users\ApterWong\AppData\Local\Programs\Python\Python36\lib\site-packages\redis\connection.py", line 590, in send_packed_command
    self._sock.sendall(item)
ConnectionResetError: [WinError 10054] è¿ç¨ä¸»æºå¼ºè¿«å³é­äºä¸ä¸ªç°æçè¿æ¥ã

During handling of the above exception, another exception occurred:

Traceback (most recent call last):
  File "C:\Users\ApterWong\AppData\Local\Programs\Python\Python36\lib\site-packages\redis\client.py", line 667, in execute_command
    connection.send_command(*args)
  File "C:\Users\ApterWong\AppData\Local\Programs\Python\Python36\lib\site-packages\redis\connection.py", line 610, in send_command
    self.send_packed_command(self.pack_command(*args))
  File "C:\Users\ApterWong\AppData\Local\Programs\Python\Python36\lib\site-packages\redis\connection.py", line 603, in send_packed_command
    (errno, errmsg))
redis.exceptions.ConnectionError: Error 10054 while writing to socket. è¿ç¨ä¸»æºå¼ºè¿«å³é­äºä¸ä¸ªç°æçè¿æ¥ã.

During handling of the above exception, another exception occurred:

Traceback (most recent call last):
  File "C:\Users\ApterWong\AppData\Local\Programs\Python\Python36\lib\site-packages\tornado\web.py", line 1541, in _execute
    result = method(*self.path_args, **self.path_kwargs)
  File "H:\stockMatchs\www\handlers\verify_code.py", line 27, in get
    raise e
  File "H:\stockMatchs\www\handlers\verify_code.py", line 24, in get
    self.redis.set("pic_code_%s" % name, VERIFY_CODE_EXPIRES_SECONDS, text.lower())
  File "C:\Users\ApterWong\AppData\Local\Programs\Python\Python36\lib\site-packages\redis\client.py", line 1171, in set
    return self.execute_command('SET', *pieces)
  File "C:\Users\ApterWong\AppData\Local\Programs\Python\Python36\lib\site-packages\redis\client.py", line 674, in execute_command
    return self.parse_response(connection, command_name, **options)
  File "C:\Users\ApterWong\AppData\Local\Programs\Python\Python36\lib\site-packages\redis\client.py", line 680, in parse_response
    response = connection.read_response()
  File "C:\Users\ApterWong\AppData\Local\Programs\Python\Python36\lib\site-packages\redis\connection.py", line 629, in read_response
    raise response
redis.exceptions.ResponseError: value is not an integer or out of range
